Traceback (most recent call last):
  File "/usr/local/lib/python3.11/site-packages/jupyter_cache/executors/utils.py", line 58, in single_nb_execution
    executenb(
  File "/usr/local/lib/python3.11/site-packages/nbclient/client.py", line 1319, in execute
    return NotebookClient(nb=nb, resources=resources, km=km, **kwargs).execute()
           ^^^^^^^^^^^^^^^^^^^^^^^^^^^^^^^^^^^^^^^^^^^^^^^^^^^^^^^^^^^^^^^^^^^^^
  File "/usr/local/lib/python3.11/site-packages/jupyter_core/utils/__init__.py", line 165, in wrapped
    return loop.run_until_complete(inner)
           ^^^^^^^^^^^^^^^^^^^^^^^^^^^^^^
  File "/usr/local/Cellar/python@3.11/3.11.9_1/Frameworks/Python.framework/Versions/3.11/lib/python3.11/asyncio/base_events.py", line 654, in run_until_complete
    return future.result()
           ^^^^^^^^^^^^^^^
  File "/usr/local/lib/python3.11/site-packages/nbclient/client.py", line 709, in async_execute
    await self.async_execute_cell(
  File "/usr/local/lib/python3.11/site-packages/nbclient/client.py", line 1062, in async_execute_cell
    await self._check_raise_for_error(cell, cell_index, exec_reply)
  File "/usr/local/lib/python3.11/site-packages/nbclient/client.py", line 918, in _check_raise_for_error
    raise CellExecutionError.from_cell_and_msg(cell, exec_reply_content)
nbclient.exceptions.CellExecutionError: An error occurred while executing the following cell:
------------------
idx        = np.random.choice(range(len(y_test)), 1)[0]
image      = X_test[idx]
prediction = predicted[idx]
test       = y_test[idx]
image = image.reshape(8, 8)
plt.imshow(image, cmap=plt.cm.gray_r)
plt.title(f'Prediction: {prediction}')
plt.show()
input('Continue (y/n) ?')
print(f'True: {test}')
------------------


[0;31m---------------------------------------------------------------------------[0m
[0;31mStdinNotImplementedError[0m                  Traceback (most recent call last)
[0;32m<ipython-input-7-162e9580d08c>[0m in [0;36m<module>[0;34m[0m
[1;32m      7[0m [0mplt[0m[0;34m.[0m[0mtitle[0m[0;34m([0m[0;34mf'Prediction: {prediction}'[0m[0;34m)[0m[0;34m[0m[0;34m[0m[0m
[1;32m      8[0m [0mplt[0m[0;34m.[0m[0mshow[0m[0;34m([0m[0;34m)[0m[0;34m[0m[0;34m[0m[0m
[0;32m----> 9[0;31m [0minput[0m[0;34m([0m[0;34m'Continue (y/n) ?'[0m[0;34m)[0m[0;34m[0m[0;34m[0m[0m
[0m[1;32m     10[0m [0mprint[0m[0;34m([0m[0;34mf'True: {test}'[0m[0;34m)[0m[0;34m[0m[0;34m[0m[0m

[0;32m~/jupyter/lib/python3.7/site-packages/ipykernel/kernelbase.py[0m in [0;36mraw_input[0;34m(self, prompt)[0m
[1;32m    844[0m         [0;32mif[0m [0;32mnot[0m [0mself[0m[0;34m.[0m[0m_allow_stdin[0m[0;34m:[0m[0;34m[0m[0;34m[0m[0m
[1;32m    845[0m             raise StdinNotImplementedError(
[0;32m--> 846[0;31m                 [0;34m"raw_input was called, but this frontend does not support input requests."[0m[0;34m[0m[0;34m[0m[0m
[0m[1;32m    847[0m             )
[1;32m    848[0m         return self._input_request(str(prompt),

[0;31mStdinNotImplementedError[0m: raw_input was called, but this frontend does not support input requests.

