Traceback (most recent call last):
  File "/Users/Xabier/Library/Python/3.9/lib/python/site-packages/jupyter_cache/executors/utils.py", line 58, in single_nb_execution
    executenb(
  File "/Users/Xabier/Library/Python/3.9/lib/python/site-packages/nbclient/client.py", line 1314, in execute
    return NotebookClient(nb=nb, resources=resources, km=km, **kwargs).execute()
  File "/Users/Xabier/Library/Python/3.9/lib/python/site-packages/jupyter_core/utils/__init__.py", line 165, in wrapped
    return loop.run_until_complete(inner)
  File "/Applications/Xcode.app/Contents/Developer/Library/Frameworks/Python3.framework/Versions/3.9/lib/python3.9/asyncio/base_events.py", line 642, in run_until_complete
    return future.result()
  File "/Users/Xabier/Library/Python/3.9/lib/python/site-packages/nbclient/client.py", line 709, in async_execute
    await self.async_execute_cell(
  File "/Users/Xabier/Library/Python/3.9/lib/python/site-packages/nbclient/client.py", line 1062, in async_execute_cell
    await self._check_raise_for_error(cell, cell_index, exec_reply)
  File "/Users/Xabier/Library/Python/3.9/lib/python/site-packages/nbclient/client.py", line 918, in _check_raise_for_error
    raise CellExecutionError.from_cell_and_msg(cell, exec_reply_content)
nbclient.exceptions.CellExecutionError: An error occurred while executing the following cell:
------------------
idx        = np.random.choice(range(len(y_test)), 1)[0]
image      = X_test[idx]
prediction = predicted[idx]
test       = y_test[idx]
image = image.reshape(8, 8)
plt.imshow(image, cmap=plt.cm.gray_r)
plt.title(f'Prediction: {prediction}')
plt.show()
input('Continue (y/n) ?')
print(f'True: {test}')
------------------


[0;31m---------------------------------------------------------------------------[0m
[0;31mStdinNotImplementedError[0m                  Traceback (most recent call last)
Cell [0;32mIn[7], line 9[0m
[1;32m      7[0m plt[38;5;241m.[39mtitle([38;5;124mf[39m[38;5;124m'[39m[38;5;124mPrediction: [39m[38;5;132;01m{[39;00mprediction[38;5;132;01m}[39;00m[38;5;124m'[39m)
[1;32m      8[0m plt[38;5;241m.[39mshow()
[0;32m----> 9[0m [38;5;28;43minput[39;49m[43m([49m[38;5;124;43m'[39;49m[38;5;124;43mContinue (y/n) ?[39;49m[38;5;124;43m'[39;49m[43m)[49m
[1;32m     10[0m [38;5;28mprint[39m([38;5;124mf[39m[38;5;124m'[39m[38;5;124mTrue: [39m[38;5;132;01m{[39;00mtest[38;5;132;01m}[39;00m[38;5;124m'[39m)

File [0;32m~/Library/Python/3.9/lib/python/site-packages/ipykernel/kernelbase.py:1281[0m, in [0;36mKernel.raw_input[0;34m(self, prompt)[0m
[1;32m   1279[0m [38;5;28;01mif[39;00m [38;5;129;01mnot[39;00m [38;5;28mself[39m[38;5;241m.[39m_allow_stdin:
[1;32m   1280[0m     msg [38;5;241m=[39m [38;5;124m"[39m[38;5;124mraw_input was called, but this frontend does not support input requests.[39m[38;5;124m"[39m
[0;32m-> 1281[0m     [38;5;28;01mraise[39;00m StdinNotImplementedError(msg)
[1;32m   1282[0m [38;5;28;01mreturn[39;00m [38;5;28mself[39m[38;5;241m.[39m_input_request(
[1;32m   1283[0m     [38;5;28mstr[39m(prompt),
[1;32m   1284[0m     [38;5;28mself[39m[38;5;241m.[39m_parent_ident[[38;5;124m"[39m[38;5;124mshell[39m[38;5;124m"[39m],
[1;32m   1285[0m     [38;5;28mself[39m[38;5;241m.[39mget_parent([38;5;124m"[39m[38;5;124mshell[39m[38;5;124m"[39m),
[1;32m   1286[0m     password[38;5;241m=[39m[38;5;28;01mFalse[39;00m,
[1;32m   1287[0m )

[0;31mStdinNotImplementedError[0m: raw_input was called, but this frontend does not support input requests.

