Traceback (most recent call last):
  File "/Users/Xabier/Library/Python/3.9/lib/python/site-packages/jupyter_cache/executors/utils.py", line 58, in single_nb_execution
    executenb(
  File "/Users/Xabier/Library/Python/3.9/lib/python/site-packages/nbclient/client.py", line 1314, in execute
    return NotebookClient(nb=nb, resources=resources, km=km, **kwargs).execute()
  File "/Users/Xabier/Library/Python/3.9/lib/python/site-packages/jupyter_core/utils/__init__.py", line 165, in wrapped
    return loop.run_until_complete(inner)
  File "/Applications/Xcode.app/Contents/Developer/Library/Frameworks/Python3.framework/Versions/3.9/lib/python3.9/asyncio/base_events.py", line 642, in run_until_complete
    return future.result()
  File "/Users/Xabier/Library/Python/3.9/lib/python/site-packages/nbclient/client.py", line 709, in async_execute
    await self.async_execute_cell(
  File "/Users/Xabier/Library/Python/3.9/lib/python/site-packages/nbclient/client.py", line 1062, in async_execute_cell
    await self._check_raise_for_error(cell, cell_index, exec_reply)
  File "/Users/Xabier/Library/Python/3.9/lib/python/site-packages/nbclient/client.py", line 918, in _check_raise_for_error
    raise CellExecutionError.from_cell_and_msg(cell, exec_reply_content)
nbclient.exceptions.CellExecutionError: An error occurred while executing the following cell:
------------------
gf.line3d   (cx, cy, cz, phirange, newfig = [fig,ax], alpha = 0.4, color = 'black');
------------------


[0;31m---------------------------------------------------------------------------[0m
[0;31mNameError[0m                                 Traceback (most recent call last)
Cell [0;32mIn[4], line 1[0m
[0;32m----> 1[0m gf[38;5;241m.[39mline3d   ([43mcx[49m, cy, cz, phirange, newfig [38;5;241m=[39m [fig,ax], alpha [38;5;241m=[39m [38;5;241m0.4[39m, color [38;5;241m=[39m [38;5;124m'[39m[38;5;124mblack[39m[38;5;124m'[39m);

[0;31mNameError[0m: name 'cx' is not defined

