Traceback (most recent call last):
  File "/Users/Xabier/Library/Python/3.9/lib/python/site-packages/jupyter_cache/executors/utils.py", line 58, in single_nb_execution
    executenb(
  File "/Users/Xabier/Library/Python/3.9/lib/python/site-packages/nbclient/client.py", line 1314, in execute
    return NotebookClient(nb=nb, resources=resources, km=km, **kwargs).execute()
  File "/Users/Xabier/Library/Python/3.9/lib/python/site-packages/jupyter_core/utils/__init__.py", line 165, in wrapped
    return loop.run_until_complete(inner)
  File "/Applications/Xcode.app/Contents/Developer/Library/Frameworks/Python3.framework/Versions/3.9/lib/python3.9/asyncio/base_events.py", line 642, in run_until_complete
    return future.result()
  File "/Users/Xabier/Library/Python/3.9/lib/python/site-packages/nbclient/client.py", line 709, in async_execute
    await self.async_execute_cell(
  File "/Users/Xabier/Library/Python/3.9/lib/python/site-packages/nbclient/client.py", line 1062, in async_execute_cell
    await self._check_raise_for_error(cell, cell_index, exec_reply)
  File "/Users/Xabier/Library/Python/3.9/lib/python/site-packages/nbclient/client.py", line 918, in _check_raise_for_error
    raise CellExecutionError.from_cell_and_msg(cell, exec_reply_content)
nbclient.exceptions.CellExecutionError: An error occurred while executing the following cell:
------------------
ts = np.linspace(0., 8*np.pi, 400)
r, w, vz = 1., 1., 2.
xs = r  * np.cos(w * ts)
ys = r  * np.sin(w * ts)
zs = vz * ts
fig = plt.figure(); ax = fig.gca(projection='3d')
ax.plot(xs, ys, zs)
plt.xlabel('$x$'); plt.ylabel('$y$'); ax.set_zlabel('z'); #plt.axis('equal')
plt.tight_layout();
------------------


[0;31m---------------------------------------------------------------------------[0m
[0;31mTypeError[0m                                 Traceback (most recent call last)
Cell [0;32mIn[3], line 6[0m
[1;32m      4[0m ys [38;5;241m=[39m r  [38;5;241m*[39m np[38;5;241m.[39msin(w [38;5;241m*[39m ts)
[1;32m      5[0m zs [38;5;241m=[39m vz [38;5;241m*[39m ts
[0;32m----> 6[0m fig [38;5;241m=[39m plt[38;5;241m.[39mfigure(); ax [38;5;241m=[39m [43mfig[49m[38;5;241;43m.[39;49m[43mgca[49m[43m([49m[43mprojection[49m[38;5;241;43m=[39;49m[38;5;124;43m'[39;49m[38;5;124;43m3d[39;49m[38;5;124;43m'[39;49m[43m)[49m
[1;32m      7[0m ax[38;5;241m.[39mplot(xs, ys, zs)
[1;32m      8[0m plt[38;5;241m.[39mxlabel([38;5;124m'[39m[38;5;124m$x$[39m[38;5;124m'[39m); plt[38;5;241m.[39mylabel([38;5;124m'[39m[38;5;124m$y$[39m[38;5;124m'[39m); ax[38;5;241m.[39mset_zlabel([38;5;124m'[39m[38;5;124mz[39m[38;5;124m'[39m); [38;5;66;03m#plt.axis('equal')[39;00m

[0;31mTypeError[0m: gca() got an unexpected keyword argument 'projection'

